Workbook

Sheet Instruções
A1: Grelhas de avaliação – Leonor Silva · Órgão 3.º grau · CRPD 2026/27
A3: Escala de 1 a 5 em cada descritor: 1 Insuficiente · 2 Em desenvolvimento · 3 Suficiente · 4 Bom · 5 Muito bom.
A4: Preencher só as células amarelas. As colunas cinzentas/azuis calculam sozinhas.
A5: Registo de aulas: 1 linha por aula (qua 45' / qui 20'). Presença: P, F, FJ (falta justificada), PM (pontualidade: chegou atrasada).
A6: Atitudinal (10%) = média de Pontualidade, Material, Empenho, Concentração, Autonomia e Estudo em casa.
A7: Tarefas em aula (40%) = média de Postura/Relaxamento, Coordenação/Técnica (inclui pedal), Leitura, Pulsação/Ritmo, Articulação/Estilo, Fraseado/Controlo.
A8: Testes (35%) e Audições/Atividades (15%): preencher na folha Testes e na folha Semestral.
A9: Ausência justificada em atividade: os 15% repartem-se igualmente por Tarefas e Testes (a folha Semestral faz isso se escrever 'J' na célula da atividade).
A10: Níveis: 1 (0–19%) · 2 (20–49%) · 3 (50–69%) · 4 (70–89%) · 5 (90–100%).
A11: Datas dos testes: 11 nov · 20 jan · 10 mar · 28 abr.

Sheet Registo de aulas
A1: Sem. | B1: Semestre | C1: Data | D1: Dia | E1: Dur. (min) | F1: Presença (P/F/FJ/PM) | G1: Pontualidade | H1: Material | I1: Empenho | J1: Concentração | K1: Autonomia / responsab. | L1: Estudo casa (1–5) | M1: Dias estudo (0–7) | N1: Min. estudo semana | O1: Postura / relaxamento | P1: Coordenação / técnica (pedal) | Q1: Leitura | R1: Pulsação / ritmo | S1: Articulação / estilo | T1: Fraseado / controlo | U1: Clave de fá (notas/min) | V1: Técnica: tonalidade | W1: ♩ técnica atingido | X1: Obra | Y1: Compassos trabalhados | Z1: ♩ obra atingido | AA1: Atitudinal (%) | AB1: Tarefas (%) | AC1: TPC | AD1: Observações (atenção, fadiga, evolução)
A2: 1 | B2: 1 | C2: 46295 | D2: qua | E2: 45 | AA2: =IFERROR(AVERAGE(G2:L2)/5,"") | AB2: =IFERROR(AVERAGE(O2:T2)/5,"")
A3: 1 | B3: 1 | C3: 46296 | D3: qui | E3: 20 | AA3: =IFERROR(AVERAGE(G3:L3)/5,"") | AB3: =IFERROR(AVERAGE(O3:T3)/5,"")
A4: 2 | B4: 1 | C4: 46302 | D4: qua | E4: 45 | AA4: =IFERROR(AVERAGE(G4:L4)/5,"") | AB4: =IFERROR(AVERAGE(O4:T4)/5,"")
A5: 2 | B5: 1 | C5: 46303 | D5: qui | E5: 20 | AA5: =IFERROR(AVERAGE(G5:L5)/5,"") | AB5: =IFERROR(AVERAGE(O5:T5)/5,"")
A6: 3 | B6: 1 | C6: 46309 | D6: qua | E6: 45 | AA6: =IFERROR(AVERAGE(G6:L6)/5,"") | AB6: =IFERROR(AVERAGE(O6:T6)/5,"")
A7: 3 | B7: 1 | C7: 46310 | D7: qui | E7: 20 | AA7: =IFERROR(AVERAGE(G7:L7)/5,"") | AB7: =IFERROR(AVERAGE(O7:T7)/5,"")
A8: 4 | B8: 1 | C8: 46316 | D8: qua | E8: 45 | AA8: =IFERROR(AVERAGE(G8:L8)/5,"") | AB8: =IFERROR(AVERAGE(O8:T8)/5,"")
A9: 4 | B9: 1 | C9: 46317 | D9: qui | E9: 20 | AA9: =IFERROR(AVERAGE(G9:L9)/5,"") | AB9: =IFERROR(AVERAGE(O9:T9)/5,"")
A10: 5 | B10: 1 | C10: 46323 | D10: qua | E10: 45 | AA10: =IFERROR(AVERAGE(G10:L10)/5,"") | AB10: =IFERROR(AVERAGE(O10:T10)/5,"")
A11: 5 | B11: 1 | C11: 46324 | D11: qui | E11: 20 | AA11: =IFERROR(AVERAGE(G11:L11)/5,"") | AB11: =IFERROR(AVERAGE(O11:T11)/5,"")
A12: 6 | B12: 1 | C12: 46330 | D12: qua | E12: 45 | AA12: =IFERROR(AVERAGE(G12:L12)/5,"") | AB12: =IFERROR(AVERAGE(O12:T12)/5,"")
A13: 6 | B13: 1 | C13: 46331 | D13: qui | E13: 20 | AA13: =IFERROR(AVERAGE(G13:L13)/5,"") | AB13: =IFERROR(AVERAGE(O13:T13)/5,"")
A14: 7 | B14: 1 | C14: 46337 | D14: qua | E14: 45 | AA14: =IFERROR(AVERAGE(G14:L14)/5,"") | AB14: =IFERROR(AVERAGE(O14:T14)/5,"") | AD14: TESTE I (1.º sem.) – Ré M/si m + Seixas
A15: 7 | B15: 1 | C15: 46338 | D15: qui | E15: 20 | AA15: =IFERROR(AVERAGE(G15:L15)/5,"") | AB15: =IFERROR(AVERAGE(O15:T15)/5,"")
A16: 8 | B16: 1 | C16: 46344 | D16: qua | E16: 45 | AA16: =IFERROR(AVERAGE(G16:L16)/5,"") | AB16: =IFERROR(AVERAGE(O16:T16)/5,"")
A17: 8 | B17: 1 | C17: 46345 | D17: qui | E17: 20 | AA17: =IFERROR(AVERAGE(G17:L17)/5,"") | AB17: =IFERROR(AVERAGE(O17:T17)/5,"")
A18: 9 | B18: 1 | C18: 46351 | D18: qua | E18: 45 | AA18: =IFERROR(AVERAGE(G18:L18)/5,"") | AB18: =IFERROR(AVERAGE(O18:T18)/5,"")
A19: 9 | B19: 1 | C19: 46352 | D19: qui | E19: 20 | AA19: =IFERROR(AVERAGE(G19:L19)/5,"") | AB19: =IFERROR(AVERAGE(O19:T19)/5,"")
A20: 10 | B20: 1 | C20: 46358 | D20: qua | E20: 45 | AA20: =IFERROR(AVERAGE(G20:L20)/5,"") | AB20: =IFERROR(AVERAGE(O20:T20)/5,"")
A21: 10 | B21: 1 | C21: 46359 | D21: qui | E21: 20 | AA21: =IFERROR(AVERAGE(G21:L21)/5,"") | AB21: =IFERROR(AVERAGE(O21:T21)/5,"")
A22: 11 | B22: 1 | C22: 46365 | D22: qua | E22: 45 | AA22: =IFERROR(AVERAGE(G22:L22)/5,"") | AB22: =IFERROR(AVERAGE(O22:T22)/5,"")
A23: 11 | B23: 1 | C23: 46366 | D23: qui | E23: 20 | AA23: =IFERROR(AVERAGE(G23:L23)/5,"") | AB23: =IFERROR(AVERAGE(O23:T23)/5,"")
A24: 12 | B24: 1 | C24: 46372 | D24: qua | E24: 45 | AA24: =IFERROR(AVERAGE(G24:L24)/5,"") | AB24: =IFERROR(AVERAGE(O24:T24)/5,"")
A25: 12 | B25: 1 | C25: 46373 | D25: qui | E25: 20 | AA25: =IFERROR(AVERAGE(G25:L25)/5,"") | AB25: =IFERROR(AVERAGE(O25:T25)/5,"")
A26: 13 | B26: 1 | C26: 46393 | D26: qua | E26: 45 | AA26: =IFERROR(AVERAGE(G26:L26)/5,"") | AB26: =IFERROR(AVERAGE(O26:T26)/5,"")
... A29: 14 | B29: 1 | C29: 46401 | D29: qui | E29: 20 | AA29: =IFERROR(AVERAGE(G29:L29)/5,"") | AB29: =IFERROR(AVERAGE(O29:T29)/5,"")
A30: 15 | B30: 1 | C30: 46407 | D30: qua | E30: 45 | AA30: =IFERROR(AVERAGE(G30:L30)/5,"") | AB30: =IFERROR(AVERAGE(O30:T30)/5,"") | AD30: TESTE II (1.º sem.) – Fá M/ré m + Loeillet + Langlais
A31: 15 | B31: 1 | C31: 46408 | D31: qui | E31: 20 | AA31: =IFERROR(AVERAGE(G31:L31)/5,"") | AB31: =IFERROR(AVERAGE(O31:T31)/5,"")
A32: 16 | B32: 2 | C32: 46421 | D32: qua | E32: 45 | AA32: =IFERROR(AVERAGE(G32:L32)/5,"") | AB32: =IFERROR(AVERAGE(O32:T32)/5,"")
A33: 16 | B33: 2 | C33: 46422 | D33: qui | E33: 20 | AA33: =IFERROR(AVERAGE(G33:L33)/5,"") | AB33: =IFERROR(AVERAGE(O33:T33)/5,"")
A34: 17 | B34: 2 | C34: 46429 | D34: qui | E34: 20 | AA34: =IFERROR(AVERAGE(G34:L34)/5,"") | AB34: =IFERROR(AVERAGE(O34:T34)/5,"")
A35: 18 | B35: 2 | C35: 46435 | D35: qua | E35: 45 | AA35: =IFERROR(AVERAGE(G35:L35)/5,"") | AB35: =IFERROR(AVERAGE(O35:T35)/5,"")
A36: 18 | B36: 2 | C36: 46436 | D36: qui | E36: 20 | AA36: =IFERROR(AVERAGE(G36:L36)/5,"") | AB36: =IFERROR(AVERAGE(O36:T36)/5,"")
A37: 19 | B37: 2 | C37: 46442 | D37: qua | E37: 45 | AA37: =IFERROR(AVERAGE(G37:L37)/5,"") | AB37: =IFERROR(AVERAGE(O37:T37)/5,"")
A38: 19 | B38: 2 | C38: 46443 | D38: qui | E38: 20 | AA38: =IFERROR(AVERAGE(G38:L38)/5,"") | AB38: =IFERROR(AVERAGE(O38:T38)/5,"")
A39: 20 | B39: 2 | C39: 46449 | D39: qua | E39: 45 | AA39: =IFERROR(AVERAGE(G39:L39)/5,"") | AB39: =IFERROR(AVERAGE(O39:T39)/5,"")
A40: 20 | B40: 2 | C40: 46450 | D40: qui | E40: 20 | AA40: =IFERROR(AVERAGE(G40:L40)/5,"") | AB40: =IFERROR(AVERAGE(O40:T40)/5,"")
A41: 21 | B41: 2 | C41: 46456 | D41: qua | E41: 45 | AA41: =IFERROR(AVERAGE(G41:L41)/5,"") | AB41: =IFERROR(AVERAGE(O41:T41)/5,"") | AD41: TESTE I (2.º sem.) – Sib M/sol m + Rheinberger
A42: 21 | B42: 2 | C42: 46457 | D42: qui | E42: 20 | AA42: =IFERROR(AVERAGE(G42:L42)/5,"") | AB42: =IFERROR(AVERAGE(O42:T42)/5,"")
...

Sheet Resumo semanal
A1: Sem. | B1: Semestre | C1: Início (qua) | D1: N.º aulas | E1: Faltas | F1: Atitudinal média | G1: Tarefas média | H1: Concentração média | I1: Clave de fá máx. notas/min | J1: Dias estudo (máx.) | K1: Meta semanal cumprida? (S/N) | L1: Metas / notas da semana
A2: 1 | B2: 1 | C2: 46295 | D2: =COUNTIF('Registo de aulas'!A:A,A2) | E2: =COUNTIFS('Registo de aulas'!A:A,A2,'Registo de aulas'!F:F,"F")+COUNTIFS('Registo de aulas'!A:A,A2,'Registo de aulas'!F:F,"FJ") | F2: =IFERROR(AVERAGEIFS('Registo de aulas'!AA:AA,'Registo de aulas'!A:A,A2),"") | G2: =IFERROR(AVERAGEIFS('Registo de aulas'!AB:AB,'Registo de aulas'!A:A,A2),"") | H2: =IFERROR(AVERAGEIFS('Registo de aulas'!J:J,'Registo de aulas'!A:A,A2),"") | I2: =IFERROR(MAXIFS('Registo de aulas'!U:U,'Registo de aulas'!A:A,A2),"") | J2: =IFERROR(MAXIFS('Registo de aulas'!M:M,'Registo de aulas'!A:A,A2),"")
A3: 2 | B3: 1 | C3: 46302 | D3: =COUNTIF('Registo de aulas'!A:A,A3) | E3: =COUNTIFS('Registo de aulas'!A:A,A3,'Registo de aulas'!F:F,"F")+COUNTIFS('Registo de aulas'!A:A,A3,'Registo de aulas'!F:F,"FJ") | F3: =IFERROR(AVERAGEIFS('Registo de aulas'!AA:AA,'Registo de aulas'!A:A,A3),"") | G3: =IFERROR(AVERAGEIFS('Registo de aulas'!AB:AB,'Registo de aulas'!A:A,A3),"") | H3: =IFERROR(AVERAGEIFS('Registo de aulas'!J:J,'Registo de aulas'!A:A,A3),"") | I3: =IFERROR(MAXIFS('Registo de aulas'!U:U,'Registo de aulas'!A:A,A3),"") | J3: =IFERROR(MAXIFS('Registo de aulas'!M:M,'Registo de aulas'!A:A,A3),"")
A4: 3 | B4: 1 | C4: 46309 | D4: =COUNTIF('Registo de aulas'!A:A,A4) | E4: =COUNTIFS('Registo de aulas'!A:A,A4,'Registo de aulas'!F:F,"F")+COUNTIFS('Registo de aulas'!A:A,A4,'Registo de aulas'!F:F,"FJ") | F4: =IFERROR(AVERAGEIFS('Registo de aulas'!AA:AA,'Registo de aulas'!A:A,A4),"") | G4: =IFERROR(AVERAGEIFS('Registo de aulas'!AB:AB,'Registo de aulas'!A:A,A4),"") | H4: =IFERROR(AVERAGEIFS('Registo de aulas'!J:J,'Registo de aulas'!A:A,A4),"") | I4: =IFERROR(MAXIFS('Registo de aulas'!U:U,'Registo de aulas'!A:A,A4),"") | J4: =IFERROR(MAXIFS('Registo de aulas'!M:M,'Registo de aulas'!A:A,A4),"")
A5: 4 | B5: 1 | C5: 46316 | D5: =COUNTIF('Registo de aulas'!A:A,A5) | E5: =COUNTIFS('Registo de aulas'!A:A,A5,'Registo de aulas'!F:F,"F")+COUNTIFS('Registo de aulas'!A:A,A5,'Registo de aulas'!F:F,"FJ") | F5: =IFERROR(AVERAGEIFS('Registo de aulas'!AA:AA,'Registo de aulas'!A:A,A5),"") | G5: =IFERROR(AVERAGEIFS('Registo de aulas'!AB:AB,'Registo de aulas'!A:A,A5),"") | H5: =IFERROR(AVERAGEIFS('Registo de aulas'!J:J,'Registo de aulas'!A:A,A5),"") | I5: =IFERROR(MAXIFS('Registo de aulas'!U:U,'Registo de aulas'!A:A,A5),"") | J5: =IFERROR(MAXIFS('Registo de aulas'!M:M,'Registo de aulas'!A:A,A5),"")
A6: 5 | B6: 1 | C6: 46323 | D6: =COUNTIF('Registo de aulas'!A:A,A6) | E6: =COUNTIFS('Registo de aulas'!A:A,A6,'Registo de aulas'!F:F,"F")+COUNTIFS('Registo de aulas'!A:A,A6,'Registo de aulas'!F:F,"FJ") | F6: =IFERROR(AVERAGEIFS('Registo de aulas'!AA:AA,'Registo de aulas'!A:A,A6),"") | G6: =IFERROR(AVERAGEIFS('Registo de aulas'!AB:AB,'Registo de aulas'!A:A,A6),"") | H6: =IFERROR(AVERAGEIFS('Registo de aulas'!J:J,'Registo de aulas'!A:A,A6),"") | I6: =IFERROR(MAXIFS('Registo de aulas'!U:U,'Registo de aulas'!A:A,A6),"") | J6: =IFERROR(MAXIFS('Registo de aulas'!M:M,'Registo de aulas'!A:A,A6),"")
A7: 6 | B7: 1 | C7: 46330 | D7: =COUNTIF('Registo de aulas'!A:A,A7) | E7: =COUNTIFS('Registo de aulas'!A:A,A7,'Registo de aulas'!F:F,"F")+COUNTIFS('Registo de aulas'!A:A,A7,'Registo de aulas'!F:F,"FJ") | F7: =IFERROR(AVERAGEIFS('Registo de aulas'!AA:AA,'Registo de aulas'!A:A,A7),"") | G7: =IFERROR(AVERAGEIFS('Registo de aulas'!AB:AB,'Registo de aulas'!A:A,A7),"") | H7: =IFERROR(AVERAGEIFS('Registo de aulas'!J:J,'Registo de aulas'!A:A,A7),"") | I7: =IFERROR(MAXIFS('Registo de aulas'!U:U,'Registo de aulas'!A:A,A7),"") | J7: =IFERROR(MAXIFS('Registo de aulas'!M:M,'Registo de aulas'!A:A,A7),"")
A8: 7 | B8: 1 | C8: 46337 | D8: =COUNTIF('Registo de aulas'!A:A,A8) | E8: =COUNTIFS('Registo de aulas'!A:A,A8,'Registo de aulas'!F:F,"F")+COUNTIFS('Registo de aulas'!A:A,A8,'Registo de aulas'!F:F,"FJ") | F8: =IFERROR(AVERAGEIFS('Registo de aulas'!AA:AA,'Registo de aulas'!A:A,A8),"") | G8: =IFERROR(AVERAGEIFS('Registo de aulas'!AB:AB,'Registo de aulas'!A:A,A8),"") | H8: =IFERROR(AVERAGEIFS('Registo de aulas'!J:J,'Registo de aulas'!A:A,A8),"") | I8: =IFERROR(MAXIFS('Registo de aulas'!U:U,'Registo de aulas'!A:A,A8),"") | J8: =IFERROR(MAXIFS('Registo de aulas'!M:M,'Registo de aulas'!A:A,A8),"")
A9: 8 | B9: 1 | C9: 46344 | D9: =COUNTIF('Registo de aulas'!A:A,A9) | E9: =COUNTIFS('Registo de aulas'!A:A,A9,'Registo de aulas'!F:F,"F")+COUNTIFS('Registo de aulas'!A:A,A9,'Registo de aulas'!F:F,"FJ") | F9: =IFERROR(AVERAGEIFS('Registo de aulas'!AA:AA,'Registo de aulas'!A:A,A9),"") | G9: =IFERROR(AVERAGEIFS('Registo de aulas'!AB:AB,'Registo de aulas'!A:A,A9),"") | H9: =IFERROR(AVERAGEIFS('Registo de aulas'!J:J,'Registo de aulas'!A:A,A9),"") | I9: =IFERROR(MAXIFS('Registo de aulas'!U:U,'Registo de aulas'!A:A,A9),"") | J9: =IFERROR(MAXIFS('Registo de aulas'!M:M,'Registo de aulas'!A:A,A9),"")
A10: 9 | B10: 1 | C10: 46351 | D10: =COUNTIF('Registo de aulas'!A:A,A10) | E10: =COUNTIFS('Registo de aulas'!A:A,A10,'Registo de aulas'!F:F,"F")+COUNTIFS('Registo de aulas'!A:A,A10,'Registo de aulas'!F:F,"FJ") | F10: =IFERROR(AVERAGEIFS('Registo de aulas'!AA:AA,'Registo de aulas'!A:A,A10),"") | G10: =IFERROR(AVERAGEIFS('Registo de aulas'!AB:AB,'Registo de aulas'!A:A,A10),"") | H10: =IFERROR(AVERAGEIFS('Registo de aulas'!J:J,'Registo de aulas'!A:A,A10),"") | I10: =IFERROR(MAXIFS('Registo de aulas'!U:U,'Registo de aulas'!A:A,A10),"") | J10: =IFERROR(MAXIFS('Registo de aulas'!M:M,'Registo de aulas'!A:A,A10),"")
A11: 10 | B11: 1 | C11: 46358 | D11: =COUNTIF('Registo de aulas'!A:A,A11) | E11: =COUNTIFS('Registo de aulas'!A:A,A11,'Registo de aulas'!F:F,"F")+COUNTIFS('Registo de aulas'!A:A,A11,'Registo de aulas'!F:F,"FJ") | F11: =IFERROR(AVERAGEIFS('Registo de aulas'!AA:AA,'Registo de aulas'!A:A,A11),"") | G11: =IFERROR(AVERAGEIFS('Registo de aulas'!AB:AB,'Registo de aulas'!A:A,A11),"") | H11: =IFERROR(AVERAGEIFS('Registo de aulas'!J:J,'Registo de aulas'!A:A,A11),"") | I11: =IFERROR(MAXIFS('Registo de aulas'!U:U,'Registo de aulas'!A:A,A11),"") | J11: =IFERROR(MAXIFS('Registo de aulas'!M:M,'Registo de aulas'!A:A,A11),"")
A12: 11 | B12: 1 | C12: 46365 | D12: =COUNTIF('Registo de aulas'!A:A,A12) | E12: =COUNTIFS('Registo de aulas'!A:A,A12,'Registo de aulas'!F:F,"F")+COUNTIFS('Registo de aulas'!A:A,A12,'Registo de aulas'!F:F,"FJ") | F12: =IFERROR(AVERAGEIFS('Registo de aulas'!AA:AA,'Registo de aulas'!A:A,A12),"") | G12: =IFERROR(AVERAGEIFS('Registo de aulas'!AB:AB,'Registo de aulas'!A:A,A12),"") | H12: =IFERROR(AVERAGEIFS('Registo de aulas'!J:J,'Registo de aulas'!A:A,A12),"") | I12: =IFERROR(MAXIFS('Registo de aulas'!U:U,'Registo de aulas'!A:A,A12),"") | J12: =IFERROR(MAXIFS('Registo de aulas'!M:M,'Registo de aulas'!A:A,A12),"")
A13: 12 | B13: 1 | C13: 46372 | D13: =COUNTIF('Registo de aulas'!A:A,A13) | E13: =COUNTIFS('Registo de aulas'!A:A,A13,'Registo de aulas'!F:F,"F")+COUNTIFS('Registo de aulas'!A:A,A13,'Registo de aulas'!F:F,"FJ") | F13: =IFERROR(AVERAGEIFS('Registo de aulas'!AA:AA,'Registo de aulas'!A:A,A13),"") | G13: =IFERROR(AVERAGEIFS('Registo de aulas'!AB:AB,'Registo de aulas'!A:A,A13),"") | H13: =IFERROR(AVERAGEIFS('Registo de aulas'!J:J,'Registo de aulas'!A:A,A13),"") | I13: =IFERROR(MAXIFS('Registo de aulas'!U:U,'Registo de aulas'!A:A,A13),"") | J13: =IFERROR(MAXIFS('Registo de aulas'!M:M,'Registo de aulas'!A:A,A13),"")
... A33: 32 | B33: 2 | C33: 46547 | D33: =COUNTIF('Registo de aulas'!A:A,A33) | E33: =COUNTIFS('Registo de aulas'!A:A,A33,'Registo de aulas'!F:F,"F")+COUNTIFS('Registo de aulas'!A:A,A33,'Registo de aulas'!F:F,"FJ") | F33: =IFERROR(AVERAGEIFS('Registo de aulas'!AA:AA,'Registo de aulas'!A:A,A33),"") | G33: =IFERROR(AVERAGEIFS('Registo de aulas'!AB:AB,'Registo de aulas'!A:A,A33),"") | H33: =IFERROR(AVERAGEIFS('Registo de aulas'!J:J,'Registo de aulas'!A:A,A33),"") | I33: =IFERROR(MAXIFS('Registo de aulas'!U:U,'Registo de aulas'!A:A,A33),"") | J33: =IFERROR(MAXIFS('Registo de aulas'!M:M,'Registo de aulas'!A:A,A33),"")

Sheet Testes
A1: Parâmetro | B1: Máx. | C1: T I – 1.º sem. 11 nov | D1: T II – 1.º sem. 20 jan | E1: T I – 2.º sem. 10 mar | F1: T II – 2.º sem. 28 abr
A2: Programa | C2: Ré M/si m · Seixas | D2: Fá M/ré m · Loeillet · Langlais | E2: Sib M/sol m · Rheinberger | F2: Mib M/dó m · Prelúdio · Pachelbel
A3: Escala maior (legato, dedilhação, pulsação) | B3: 8
A4: Escala menor (harmónica + melódica) | B4: 8
A5: Arpejos | B5: 6
A6: Acordes + cadências 3 posições (nota comum presa) | B6: 8
A7: Obra(s): leitura / texto correto | B7: 15
A8: Pulsação estável e rigor rítmico | B8: 15
A9: Articulação e adequação estilística | B9: 12
A10: Fraseado e expressividade | B10: 10
A11: Coordenação / técnica (pedal) e registação | B11: 10
A12: Apresentação e postura | B12: 8
A13: TOTAL (%) | B13: =SUM(B3:B12) | C13: =IF(COUNT(C3:C12)=0,"",SUM(C3:C12)/100) | D13: =IF(COUNT(D3:D12)=0,"",SUM(D3:D12)/100) | E13: =IF(COUNT(E3:E12)=0,"",SUM(E3:E12)/100) | F13: =IF(COUNT(F3:F12)=0,"",SUM(F3:F12)/100)
A14: Júri / observações

Sheet Semestral
A1: Domínio / instrumento | B1: Ponderação | C1: 1.º semestre | D1: 2.º semestre | E1: Notas
A2: Atitudinal – observação direta / registos diários | B2: 0.1 | C2: =IFERROR(AVERAGEIFS('Registo de aulas'!AA:AA,'Registo de aulas'!B:B,1),"") | D2: =IFERROR(AVERAGEIFS('Registo de aulas'!AA:AA,'Registo de aulas'!B:B,2),"") | E2: Média automática das aulas
A3: Desempenho – observação / tarefas em aula | B3: 0.4 | C3: =IFERROR(AVERAGEIFS('Registo de aulas'!AB:AB,'Registo de aulas'!B:B,1),"") | D3: =IFERROR(AVERAGEIFS('Registo de aulas'!AB:AB,'Registo de aulas'!B:B,2),"") | E3: Média automática das aulas
A4: Desempenho – testes | B4: 0.35 | C4: =IFERROR(AVERAGE(Testes!C13:D13),"") | D4: =IFERROR(AVERAGE(Testes!E13:F13),"") | E4: Média dos 2 momentos do semestre
A5: Audições / apresentações / atividades | B5: 0.15 | E5: Escrever % (ex.: 80%) ou J = ausência justificada
A6: Atividade realizada (descrição) | C6: Apresentação em aula dez / Itinerários S. José | D6: Itinerários Maia / Encontro musical maio
A8: CLASSIFICAÇÃO DO SEMESTRE (%) | C8: =IFERROR(IF(UPPER(C5)="J",C2*$B$2+C3*($B$3+$B$5/2)+C4*($B$4+$B$5/2),C2*$B$2+C3*$B$3+C4*$B$4+C5*$B$5),"") | D8: =IFERROR(IF(UPPER(D5)="J",D2*$B$2+D3*($B$3+$B$5/2)+D4*($B$4+$B$5/2),D2*$B$2+D3*$B$3+D4*$B$4+D5*$B$5),"")
A9: Nível do semestre (1–5) | C9: =IF(C8="","",IF(C8<0.2,1,IF(C8<0.5,2,IF(C8<0.7,3,IF(C8<0.9,4,5))))) | D9: =IF(D8="","",IF(D8<0.2,1,IF(D8<0.5,2,IF(D8<0.7,3,IF(D8<0.9,4,5)))))
A11: CLASSIFICAÇÃO FINAL (média simples dos semestres, %) | C11: =IFERROR(AVERAGE(C8:D8),"")
A12: NÍVEL FINAL (considerar a evolução da aluna) | C12: =IF(C11="","",IF(C11<0.2,1,IF(C11<0.5,2,IF(C11<0.7,3,IF(C11<0.9,4,5)))))
A14: Síntese descritiva 1.º semestre
A15: Síntese descritiva 2.º semestre

Sheet Metrónomo
A1: Obra / técnica | B1: Unidade | C1: Leitura | D1: Meta C-1 | E1: Meta C-2 | F1: Andamento de prova | G1: Andamento de segurança | H1: Sem. 1 | I1: Sem. 2 | J1: Sem. 3 | K1: Sem. 4 | L1: Sem. 5 | M1: Sem. 6 | N1: Sem. 7 | O1: Sem. 8 | P1: Sem. 9 | Q1: Sem. 10 | R1: Sem. 11 | S1: Sem. 12 | T1: Sem. 13 | U1: Sem. 14 | V1: Sem. 15 | W1: Sem. 16 | X1: Sem. 17 | Y1: Sem. 18 | Z1: Sem. 19 | AA1: Sem. 20 | AB1: Sem. 21 | AC1: Sem. 22 | AD1: Sem. 23 | AE1: Sem. 24 | AF1: Sem. 25 | AG1: Sem. 26
A2: Ré M / si m escalas | B2: ♩ (colch.) | C2: 60 | D2: 72 | E2: 80 | F2: 84–88 | G2: 76
A3: Seixas | B3: ♩. | C3: 40 | D3: 46 | E3: 56 | F3: 60–66 | G3: 56
A4: Fá M / ré m escalas | B4: ♩ (colch.) | C4: 60 | D4: 76 | E4: 84 | F4: 88 | G4: 80
A5: Loeillet | B5: ♩ | C5: 60 | D5: 72 | E5: 88 | F5: 96–104 | G5: 88
A6: Langlais | B6: ♩ | C6: 56 | D6: 66 | E6: 76 | F6: 80–88 | G6: 72
A7: Sib M / sol m escalas | B7: ♩ (colch.) | C7: 60 | D7: 72 | E7: 80 | F7: 84 | G7: 76
A8: Rheinberger | B8: ♩. | C8: 33 | D8: 40 | E8: 44 | F8: 44–50 | G8: 40
A9: Mib M / dó m escalas | B9: ♩ (colch.) | C9: 60 | D9: 72 | E9: 80 | F9: 84 | G9: 76
A10: Pachelbel | B10: ♩. | C10: 33 | D10: 40 | E10: 48 | F10: 48–56 | G10: 44
A11: Prelúdio (sol m) | B11: 𝅗𝅥 | C11: 40 | D11: 48 | E11: 54 | F11: 56–63 | G11: 50

Sheet Estudo em casa
A1: Sem. | B1: Início (seg) | C1: Seg | D1: Ter | E1: Qua | F1: Qui | G1: Sex | H1: Sáb | I1: Dom | J1: Dias | K1: Minutos totais | L1: Recorde clave fá | M1: Assinatura EE (S/N) | N1: Obs.
A2: Escrever em cada dia os minutos de estudo (0 = não estudou).
A3: 1 | B3: 46293 | J3: =COUNTIF(C3:I3,">0") | K3: =SUM(C3:I3)
A4: 2 | B4: 46300 | J4: =COUNTIF(C4:I4,">0") | K4: =SUM(C4:I4)
A5: 3 | B5: 46307 | J5: =COUNTIF(C5:I5,">0") | K5: =SUM(C5:I5)
A6: 4 | B6: 46314 | J6: =COUNTIF(C6:I6,">0") | K6: =SUM(C6:I6)
A7: 5 | B7: 46321 | J7: =COUNTIF(C7:I7,">0") | K7: =SUM(C7:I7)
A8: 6 | B8: 46328 | J8: =COUNTIF(C8:I8,">0") | K8: =SUM(C8:I8)
A9: 7 | B9: 46335 | J9: =COUNTIF(C9:I9,">0") | K9: =SUM(C9:I9)
A10: 8 | B10: 46342 | J10: =COUNTIF(C10:I10,">0") | K10: =SUM(C10:I10)
A11: 9 | B11: 46349 | J11: =COUNTIF(C11:I11,">0") | K11: =SUM(C11:I11)
A12: 10 | B12: 46356 | J12: =COUNTIF(C12:I12,">0") | K12: =SUM(C12:I12)
A13: 11 | B13: 46363 | J13: =COUNTIF(C13:I13,">0") | K13: =SUM(C13:I13)
A14: 12 | B14: 46370 | J14: =COUNTIF(C14:I14,">0") | K14: =SUM(C14:I14)
... A34: 32 | B34: 46545 | J34: =COUNTIF(C34:I34,">0") | K34: =SUM(C34:I34)
